Workbook

Sheet Calcs by Scenario
A1: Scenario | B1: Vehicle Type | C1: VMT | D1: Gas VMT (B) | E1: MPG | F1: Gallons (B) | G1: Carbon Intensity (kg CO2 / gallon) | H1: Gas Emissions (M tons CO2) | I1: Electric VMT (B) | J1: % Electric | K1: % Increase Change | L1: mi / kWh | M1: Electricity (TWh) | N1: Carbon Intensity g CO2 / kWh | O1: Electricity Emissions (M t CO2) | P1: Total Emissions (M t CO2) | Q1: CO2 Saved (M t CO2) | R1: Average Battery Size (kWh) | S1: Installed Battery (TWh) | T1: Installed Battery (Wh) / mile | U1: Cost / kWh | V1: $T Installed Battery | W1: $ CAPEX / kg CO2 | X1: $ CAPEX / EV Mile | Y1: $ / gallon | Z1: $ B OC Gas | AA1: $ / kWh | AB1: $B OC ELC | AC1: $B OC Total | AD1: $B ELC Savings | AE1: $ OC / VMT | AF1: $OC / kg CO2
A2: Worst | B2: ICE | C2: 3262.8 | D2: =C2*1 -> 3262.8 | E2: 36 | F2: =D2/E2 -> 90.633333 | G2: 8.888 | H2: =F2*G2 -> 805.54907 | I2: =C2-D2 -> 0 | J2: =I2/C2 -> 0 | L2: 2.9 | M2: =I2/L2 -> 0 | N2: 714 | O2: =M2*N2*1000 -> 0 | P2: =O2+H2 -> 805.54907 | Q2: =$P$2-P2 -> 0 | R2: =0/L2 -> 0 | S2: =R2*Rough1!$B$25/1000000/1000 -> 0 | T2: =S2/C2*1000 -> 0 | U2: 150 | V2: =S2*U2/1000 -> 0 | W2: N/A | X2: N/A | Y2: 2 | Z2: =Y2*F2 -> 181.26667 | AA2: 0.4 | AB2: =AA2*M2 -> 0 | AC2: =AB2+Z2 -> 181.26667 | AD2: =$AC$2-AC2 -> 0 | AE2: =AC2/C2 -> 0.055555556 | AF2: N/A
A3: Worst | B3: LDV (25-mile EV range) | C3: 3262.8 | D3: 1326.0507 | E3: =E2 -> 36 | F3: =D3/E3 -> 36.834743 | G3: 8.888 | H3: =F3*G3 -> 327.38719 | I3: =C3-D3 -> 1936.7493 | J3: =I3/C3 -> 0.59358504 | K3: =J3-J2 -> 0.59358504 | L3: =L2 -> 2.9 | M3: =I3/L3 -> 667.84457 | N3: =N2 -> 714 | O3: =M3*N3*1000/1000000 -> 476.84102 | P3: =O3+H3 -> 804.22822 | Q3: =$P$2-P3 -> 1.3208482 | R3: =25/L3 -> 8.6206897 | S3: =R3*Rough1!$B$25/1000000/1000 -> 2.221907 | T3: =S3/C3*1000 -> 0.68098169 | U3: =U2 -> 150 | V3: =S3*U3/1000 -> 0.33328606 | W3: =V3/(Q3*Rough1!$B$26)*1000 -> 25.232731 | X3: =V3/(I3*Rough1!$B$26)*1000 -> 0.017208529 | Y3: 2 | Z3: =Y3*F3 -> 73.669486 | AA3: 0.4 | AB3: =AA3*M3 -> 267.13783 | AC3: =AB3+Z3 -> 340.80731 | AD3: =$AC$2-AC3 -> -159.54065 | AE3: =AC3/C3 -> 0.10445241 | AF3: =AC3/Q3 -> 258.02157
A4: Worst | B4: LDV (50-mile EV range) | C4: 3262.8 | D4: 871.73127 | E4: =E3 -> 36 | F4: =D4/E4 -> 24.214758 | G4: 8.888 | H4: =F4*G4 -> 215.22076 | I4: =C4-D4 -> 2391.0687 | J4: =I4/C4 -> 0.73282724 | K4: =J4-J3 -> 0.13924221 | L4: =L3 -> 2.9 | M4: =I4/L4 -> 824.50646 | N4: =N3 -> 714 | O4: =M4*N4*1000/1000000 -> 588.69761 | P4: =O4+H4 -> 803.91838 | Q4: =$P$2-P4 -> 1.6306906 | R4: =50/L4 -> 17.241379 | S4: =R4*Rough1!$B$25/1000000/1000 -> 4.4438141 | T4: =S4/C4*1000 -> 1.3619634 | U4: =U3 -> 150 | V4: =S4*U4/1000 -> 0.66657211 | W4: =V4/(Q4*Rough1!$B$26)*1000 -> 40.876677 | X4: =V4/(I4*Rough1!$B$26)*1000 -> 0.027877581 | Y4: 2 | Z4: =Y4*F4 -> 48.429515 | AA4: 0.4 | AB4: =AA4*M4 -> 329.80258 | AC4: =AB4+Z4 -> 378.2321 | AD4: =$AC$2-AC4 -> -196.96543 | AE4: =AC4/C4 -> 0.11592255 | AF4: =AC4/Q4 -> 231.94597
A5: Worst | B5: LDV (75-mile EV range) | C5: 3262.8 | D5: 711.79192 | E5: =E4 -> 36 | F5: =D5/E5 -> 19.771998 | G5: 8.888 | H5: =F5*G5 -> 175.73352 | I5: =C5-D5 -> 2551.0081 | J5: =I5/C5 -> 0.78184629 | K5: =J5-J4 -> 0.049019048 | L5: =L4 -> 2.9 | M5: =I5/L5 -> 879.65796 | N5: =N4 -> 714 | O5: =M5*N5*1000/1000000 -> 628.07578 | P5: =O5+H5 -> 803.8093 | Q5: =$P$2-P5 -> 1.739768 | R5: =75/L5 -> 25.862069 | S5: =R5*Rough1!$B$25/1000000/1000 -> 6.6657211 | T5: =S5/C5*1000 -> 2.0429451 | U5: =U4 -> 150 | V5: =S5*U5/1000 -> 0.99985817 | W5: =V5/(Q5*Rough1!$B$26)*1000 -> 57.470777 | X5: =V5/(I5*Rough1!$B$26)*1000 -> 0.03919463 | Y5: 2 | Z5: =Y5*F5 -> 39.543996 | AA5: 0.4 | AB5: =AA5*M5 -> 351.86318 | AC5: =AB5+Z5 -> 391.40718 | AD5: =$AC$2-AC5 -> -210.14051 | AE5: =AC5/C5 -> 0.11996052 | AF5: =AC5/Q5 -> 224.97666
A6: Worst | B6: LDV (100-mile EV range) | C6: 3262.8 | D6: 551.85257 | E6: =E5 -> 36 | F6: =D6/E6 -> 15.329238 | G6: 8.888 | H6: =F6*G6 -> 136.24627 | I6: =C6-D6 -> 2710.9474 | J6: =I6/C6 -> 0.83086534 | K6: =J6-J5 -> 0.049019048 | L6: =L5 -> 2.9 | M6: =I6/L6 -> 934.80946 | N6: =N5 -> 714 | O6: =M6*N6*1000/1000000 -> 667.45395 | P6: =O6+H6 -> 803.70022 | Q6: =$P$2-P6 -> 1.8488454 | R6: =100/L6 -> 34.482759 | S6: =R6*Rough1!$B$25/1000000/1000 -> 8.8876282 | T6: =S6/C6*1000 -> 2.7239267 | U6: =U5 -> 150 | V6: =S6*U6/1000 -> 1.3331442 | W6: =V6/(Q6*Rough1!$B$26)*1000 -> 72.106854 | X6: =V6/(I6*Rough1!$B$26)*1000 -> 0.049176322 | Y6: 2 | Z6: =Y6*F6 -> 30.658476 | AA6: 0.4 | AB6: =AA6*M6 -> 373.92378 | AC6: =AB6+Z6 -> 404.58226 | AD6: =$AC$2-AC6 -> -223.31559 | AE6: =AC6/C6 -> 0.12399849 | AF6: =AC6/Q6 -> 218.82969
A7: Worst | B7: LDV (125-mile EV range) | C7: 3262.8 | D7: 491.22464 | E7: =E6 -> 36 | F7: =D7/E7 -> 13.645129 | G7: 8.888 | H7: =F7*G7 -> 121.27791 | I7: =C7-D7 -> 2771.5754 | J7: =I7/C7 -> 0.84944691 | K7: =J7-J6 -> 0.018581565 | L7: =L6 -> 2.9 | M7: =I7/L7 -> 955.71564 | N7: =N6 -> 714 | O7: =M7*N7*1000/1000000 -> 682.38097 | P7: =O7+H7 -> 803.65887 | Q7: =$P$2-P7 -> 1.8901932 | R7: =125/L7 -> 43.103448 | S7: =R7*Rough1!$B$25/1000000/1000 -> 11.109535 | T7: =S7/C7*1000 -> 3.4049084 | U7: =U6 -> 150 | V7: =S7*U7/1000 -> 1.6664303 | W7: =V7/(Q7*Rough1!$B$26)*1000 -> 88.161904 | X7: =V7/(I7*Rough1!$B$26)*1000 -> 0.060125743 | Y7: 2 | Z7: =Y7*F7 -> 27.290258 | AA7: 0.4 | AB7: =AA7*M7 -> 382.28626 | AC7: =AB7+Z7 -> 409.57651 | AD7: =$AC$2-AC7 -> -228.30985 | AE7: =AC7/C7 -> 0.12552915 | AF7: =AC7/Q7 -> 216.68501
A8: Worst | B8: LDV (150-mile EV range) | C8: 3262.8 | D8: 430.59671 | E8: =E7 -> 36 | F8: =D8/E8 -> 11.96102 | G8: 8.888 | H8: =F8*G8 -> 106.30954 | I8: =C8-D8 -> 2832.2033 | J8: =I8/C8 -> 0.86802847 | K8: =J8-J7 -> 0.018581566 | L8: =L7 -> 2.9 | M8: =I8/L8 -> 976.62183 | N8: =N7 -> 714 | O8: =M8*N8*1000/1000000 -> 697.30798 | P8: =O8+H8 -> 803.61753 | Q8: =$P$2-P8 -> 1.9315409 | R8: =150/L8 -> 51.724138 | S8: =R8*Rough1!$B$25/1000000/1000 -> 13.331442 | T8: =S8/C8*1000 -> 4.0858901 | U8: =U7 -> 150 | V8: =S8*U8/1000 -> 1.9997163 | W8: =V8/(Q8*Rough1!$B$26)*1000 -> 103.52959 | X8: =V8/(I8*Rough1!$B$26)*1000 -> 0.070606384 | Y8: 2 | Z8: =Y8*F8 -> 23.922039 | AA8: 0.4 | AB8: =AA8*M8 -> 390.64873 | AC8: =AB8+Z8 -> 414.57077 | AD8: =$AC$2-AC8 -> -233.3041 | AE8: =AC8/C8 -> 0.12705982 | AF8: =AC8/Q8 -> 214.63214
A9: Worst | B9: EV | C9: 3262.8 | D9: =C9*0 -> 0 | E9: =E8 -> 36 | F9: =D9/E9 -> 0 | G9: 8.888 | H9: =F9*G9 -> 0 | I9: =C9-D9 -> 3262.8 | J9: =I9/C9 -> 1 | K9: =J9-J8 -> 0.13197153 | L9: =L8 -> 2.9 | M9: =I9/L9 -> 1125.1034 | N9: =N8 -> 714 | O9: =M9*N9*1000/1000000 -> 803.32386 | P9: =O9+H9 -> 803.32386 | Q9: =$P$2-P9 -> 2.2252046 | R9: =300/L9 -> 103.44828 | S9: =R9*Rough1!$B$25/1000000/1000 -> 26.662885 | T9: =S9/C9*1000 -> 8.1717802 | U9: =U8 -> 150 | V9: =S9*U9/1000 -> 3.9994327 | W9: =V9/(Q9*Rough1!$B$26)*1000 -> 179.73326 | X9: =V9/(I9*Rough1!$B$26)*1000 -> 0.1225767 | Y9: 2 | Z9: =Y9*F9 -> 0 | AA9: 0.4 | AB9: =AA9*M9 -> 450.04138 | AC9: =AB9+Z9 -> 450.04138 | AD9: =$AC$2-AC9 -> -268.77471 | AE9: =AC9/C9 -> 0.13793103 | AF9: =AC9/Q9 -> 202.24719
A10: Average | B10: ICE | C10: 3262.8 | D10: =C10*1 -> 3262.8 | E10: 26.4 | F10: =D10/E10 -> 123.59091 | G10: 8.888 | H10: =F10*G10 -> 1098.476 | I10: =C10-D10 -> 0 | J10: =I10/C10 -> 0 | L10: 3.6 | M10: =I10/L10 -> 0 | N10: 348 | O10: =M10*N10*1000/1000000 -> 0 | P10: =O10+H10 -> 1098.476 | Q10: =$P$10-P10 -> 0 | R10: =0/L10 -> 0 | S10: =R10*Rough1!$B$25/1000000/1000 -> 0 | T10: =S10/C10*1000 -> 0 | U10: 115 | V10: =S10*U10/1000 -> 0 | W10: N/A | X10: N/A | Y10: 3 | Z10: =Y10*F10 -> 370.77273 | AA10: 0.25 | AB10: =AA10*M10 -> 0 | AC10: =AB10+Z10 -> 370.77273 | AD10: =$AC$10-AC10 -> 0 | AE10: =AC10/C10 -> 0.11363636 | AF10: N/A
A11: Average | B11: LDV (25-mile EV range) | C11: 3262.8 | D11: 1326.0507 | E11: 26.4 | F11: =D11/E11 -> 50.229195 | G11: 8.888 | H11: =F11*G11 -> 446.43708 | I11: =C11-D11 -> 1936.7493 | J11: =I11/C11 -> 0.59358504 | K11: =J11-J10 -> 0.59358504 | L11: 3.6 | M11: =I11/L11 -> 537.98591 | N11: 348 | O11: =M11*N11*1000/1000000 -> 187.21909 | P11: =O11+H11 -> 633.65618 | Q11: =$P$10-P11 -> 464.81982 | R11: =25/L11 -> 6.9444444 | S11: =R11*Rough1!$B$25/1000000/1000 -> 1.7898696 | T11: =S11/C11*1000 -> 0.54856858 | U11: =U10 -> 115 | V11: =S11*U11/1000 -> 0.205835 | W11: =V11/(Q11*Rough1!$B$26)*1000 -> 0.04428275 | X11: =V11/(I11*Rough1!$B$26)*1000 -> 0.01062786 | Y11: 3 | Z11: =Y11*F11 -> 150.68758 | AA11: 0.25 | AB11: =AA11*M11 -> 134.49648 | AC11: =AB11+Z11 -> 285.18406 | AD11: =$AC$10-AC11 -> 85.588667 | AE11: =AC11/C11 -> 0.087404702 | AF11: =AC11/Q11 -> 0.61353679
A12: Average | B12: LDV (50-mile EV range) | C12: 3262.8 | D12: 871.73127 | E12: 26.4 | F12: =D12/E12 -> 33.020124 | G12: 8.888 | H12: =F12*G12 -> 293.48286 | I12: =C12-D12 -> 2391.0687 | J12: =I12/C12 -> 0.73282724 | K12: =J12-J11 -> 0.13924221 | L12: 3.6 | M12: =I12/L12 -> 664.18576 | N12: 348 | O12: =M12*N12*1000/1000000 -> 231.13664 | P12: =O12+H12 -> 524.6195 | Q12: =$P$10-P12 -> 573.8565 | R12: =50/L12 -> 13.888889 | S12: =R12*Rough1!$B$25/1000000/1000 -> 3.5797391 | T12: =S12/C12*1000 -> 1.0971372 | U12: =U11 -> 115 | V12: =S12*U12/1000 -> 0.41167 | W12: =V12/(Q12*Rough1!$B$26)*1000 -> 0.071737447 | X12: =V12/(I12*Rough1!$B$26)*1000 -> 0.017216987 | Y12: 3 | Z12: =Y12*F12 -> 99.060372 | AA12: 0.25 | AB12: =AA12*M12 -> 166.04644 | AC12: =AB12+Z12 -> 265.10681 | AD12: =$AC$10-AC12 -> 105.66592 | AE12: =AC12/C12 -> 0.081251321 | AF12: =AC12/Q12 -> 0.46197405
A13: Average | B13: LDV (75-mile EV range) | C13: 3262.8 | D13: 711.79192 | E13: 26.4 | F13: =D13/E13 -> 26.961815 | G13: 8.888 | H13: =F13*G13 -> 239.63661 | I13: =C13-D13 -> 2551.0081 | J13: =I13/C13 -> 0.78184629 | K13: =J13-J12 -> 0.049019048 | L13: 3.6 | M13: =I13/L13 -> 708.61336 | N13: 348 | O13: =M13*N13*1000/1000000 -> 246.59745 | P13: =O13+H13 -> 486.23406 | Q13: =$P$10-P13 -> 612.24194 | R13: =75/L13 -> 20.833333 | S13: =R13*Rough1!$B$25/1000000/1000 -> 5.3696087 | T13: =S13/C13*1000 -> 1.6457057 | U13: =U12 -> 115 | V13: =S13*U13/1000 -> 0.617505 | W13: =V13/(Q13*Rough1!$B$26)*1000 -> 0.10085964 | X13: =V13/(I13*Rough1!$B$26)*1000 -> 0.024206313 | Y13: 3 | Z13: =Y13*F13 -> 80.885445 | AA13: 0.25 | AB13: =AA13*M13 -> 177.15334 | AC13: =AB13+Z13 -> 258.03878 | AD13: =$AC$10-AC13 -> 112.73394 | AE13: =AC13/C13 -> 0.079085076 | AF13: =AC13/Q13 -> 0.42146538
A14: Average | B14: LDV (100-mile EV range) | C14: 3262.8 | D14: 551.85257 | E14: 26.4 | F14: =D14/E14 -> 20.903506 | G14: 8.888 | H14: =F14*G14 -> 185.79036 | I14: =C14-D14 -> 2710.9474 | J14: =I14/C14 -> 0.83086534 | K14: =J14-J13 -> 0.049019048 | L14: 3.6 | M14: =I14/L14 -> 753.04095 | N14: 348 | O14: =M14*N14*1000/1000000 -> 262.05825 | P14: =O14+H14 -> 447.84862 | Q14: =$P$10-P14 -> 650.62738 | R14: =100/L14 -> 27.777778 | S14: =R14*Rough1!$B$25/1000000/1000 -> 7.1594783 | T14: =S14/C14*1000 -> 2.1942743 | U14: =U13 -> 115 | V14: =S14*U14/1000 -> 0.82334 | W14: =V14/(Q14*Rough1!$B$26)*1000 -> 0.12654555 | X14: =V14/(I14*Rough1!$B$26)*1000 -> 0.030370932 | Y14: 3 | Z14: =Y14*F14 -> 62.710519 | AA14: 0.25 | AB14: =AA14*M14 -> 188.26024 | AC14: =AB14+Z14 -> 250.97076 | AD14: =$AC$10-AC14 -> 119.80197 | AE14: =AC14/C14 -> 0.07691883 | AF14: =AC14/Q14 -> 0.38573654
A15: Average | B15: LDV (125-mile EV range) | C15: 3262.8 | D15: 491.22464 | E15: 26.4 | F15: =D15/E15 -> 18.606994 | G15: 8.888 | H15: =F15*G15 -> 165.37896 | I15: =C15-D15 -> 2771.5754 | J15: =I15/C15 -> 0.84944691 | K15: =J15-J14 -> 0.018581565 | L15: 3.6 | M15: =I15/L15 -> 769.88204 | N15: 348 | O15: =M15*N15*1000/1000000 -> 267.91895 | P15: =O15+H15 -> 433.29791 | Q15: =$P$10-P15 -> 665.17809 | R15: =125/L15 -> 34.722222 | S15: =R15*Rough1!$B$25/1000000/1000 -> 8.9493478 | T15: =S15/C15*1000 -> 2.7428429 | U15: =U14 -> 115 | V15: =S15*U15/1000 -> 1.029175 | W15: =V15/(Q15*Rough1!$B$26)*1000 -> 0.15472172 | X15: =V15/(I15*Rough1!$B$26)*1000 -> 0.037133214 | Y15: 3 | Z15: =Y15*F15 -> 55.820982 | AA15: 0.25 | AB15: =AA15*M15 -> 192.47051 | AC15: =AB15+Z15 -> 248.29149 | AD15: =$AC$10-AC15 -> 122.48123 | AE15: =AC15/C15 -> 0.076097675 | AF15: =AC15/Q15 -> 0.3732707
A16: Average | B16: LDV (150-mile EV range) | C16: 3262.8 | D16: 430.59671 | E16: 26.4 | F16: =D16/E16 -> 16.310481 | G16: 8.888 | H16: =F16*G16 -> 144.96756 | I16: =C16-D16 -> 2832.2033 | J16: =I16/C16 -> 0.86802847 | K16: =J16-J15 -> 0.018581566 | L16: 3.6 | M16: =I16/L16 -> 786.72314 | N16: 348 | O16: =M16*N16*1000/1000000 -> 273.77965 | P16: =O16+H16 -> 418.74721 | Q16: =$P$10-P16 -> 679.72879 | R16: =150/L16 -> 41.666667 | S16: =R16*Rough1!$B$25/1000000/1000 -> 10.739217 | T16: =S16/C16*1000 -> 3.2914115 | U16: =U15 -> 115 | V16: =S16*U16/1000 -> 1.23501 | W16: =V16/(Q16*Rough1!$B$26)*1000 -> 0.18169158 | X16: =V16/(I16*Rough1!$B$26)*1000 -> 0.04360598 | Y16: 3 | Z16: =Y16*F16 -> 48.931444 | AA16: 0.25 | AB16: =AA16*M16 -> 196.68078 | AC16: =AB16+Z16 -> 245.61223 | AD16: =$AC$10-AC16 -> 125.1605 | AE16: =AC16/C16 -> 0.07527652 | AF16: =AC16/Q16 -> 0.36133857
A17: Average | B17: EV | C17: 3262.8 | D17: =C17*0 -> 0 | E17: 26.4 | F17: =D17/E17 -> 0 | G17: 8.888 | H17: =F17*G17 -> 0 | I17: =C17-D17 -> 3262.8 | J17: =I17/C17 -> 1 | K17: =J17-J16 -> 0.13197153 | L17: 3.6 | M17: =I17/L17 -> 906.33333 | N17: 348 | O17: =M17*N17*1000/1000000 -> 315.404 | P17: =O17+H17 -> 315.404 | Q17: =$P$10-P17 -> 783.072 | R17: =300/L17 -> 83.333333 | S17: =R17*Rough1!$B$25/1000000/1000 -> 21.478435 | T17: =S17/C17*1000 -> 6.582823 | U17: =U16 -> 115 | V17: =S17*U17/1000 -> 2.47002 | W17: =V17/(Q17*Rough1!$B$26)*1000 -> 0.31542693 | X17: =V17/(I17*Rough1!$B$26)*1000 -> 0.075702464 | Y17: 3 | Z17: =Y17*F17 -> 0 | AA17: 0.15 | AB17: =AA17*M17 -> 135.95 | AC17: =AB17+Z17 -> 135.95 | AD17: =$AC$10-AC17 -> 234.82273 | AE17: =AC17/C17 -> 0.041666667 | AF17: =AC17/Q17 -> 0.17361111
A18: Best | B18: ICE | C18: 3262.8 | D18: =C18*1 -> 3262.8 | E18: 18 | F18: =D18/E18 -> 181.26667 | G18: 8.888 | H18: =F18*G18 -> 1611.0981 | I18: =C18-D18 -> 0 | J18: =I18/C18 -> 0 | L18: 4.2 | M18: =I18/L18 -> 0 | N18: 125 | O18: =M18*N18*1000/1000000 -> 0 | P18: =O18+H18 -> 1611.0981 | Q18: =$P$18-P18 -> 0 | R18: =0/L18 -> 0 | S18: =R18*Rough1!$B$25/1000000/1000 -> 0 | T18: =S18/C18*1000 -> 0 | U18: 75 | V18: =S18*U18/1000 -> 0 | W18: N/A | X18: N/A | Y18: 5 | Z18: =Y18*F18 -> 906.33333 | AA18: 0.15 | AB18: =AA18*M18 -> 0 | AC18: =AB18+Z18 -> 906.33333 | AD18: =$AC$18-AC18 -> 0 | AE18: =AC18/C18 -> 0.27777778 | AF18: N/A
A19: Best | B19: LDV (25-mile EV range) | C19: 3262.8 | D19: 1326.0507 | E19: 18 | F19: =D19/E19 -> 73.669486 | G19: 8.888 | H19: =F19*G19 -> 654.77439 | I19: =C19-D19 -> 1936.7493 | J19: =I19/C19 -> 0.59358504 | K19: =J19-J18 -> 0.59358504 | L19: =L18 -> 4.2 | M19: =I19/L19 -> 461.13078 | N19: 125 | O19: =M19*N19*1000/1000000 -> 57.641347 | P19: =O19+H19 -> 712.41574 | Q19: =$P$18-P19 -> 898.6824 | R19: =25/L19 -> 5.952381 | S19: =R19*Rough1!$B$25/1000000/1000 -> 1.5341739 | T19: =S19/C19*1000 -> 0.47020164 | U19: 75 | V19: =S19*U19/1000 -> 0.11506304 | W19: =V19/(Q19*Rough1!$B$26)*1000 -> 0.012803527 | X19: =V19/(I19*Rough1!$B$26)*1000 -> 0.0059410398 | Y19: 5 | Z19: =Y19*F19 -> 368.34743 | AA19: 0.15 | AB19: =AA19*M19 -> 69.169616 | AC19: =AB19+Z19 -> 437.51704 | AD19: =$AC$18-AC19 -> 468.81629 | AE19: =AC19/C19 -> 0.13409251 | AF19: =AC19/Q19 -> 0.48684279
A20: Best | B20: LDV (50-mile EV range) | C20: 3262.8 | D20: 871.73127 | E20: 18 | F20: =D20/E20 -> 48.429515 | G20: 8.888 | H20: =F20*G20 -> 430.44153 | I20: =C20-D20 -> 2391.0687 | J20: =I20/C20 -> 0.73282724 | K20: =J20-J19 -> 0.13924221 | L20: =L19 -> 4.2 | M20: =I20/L20 -> 569.30208 | N20: 125 | O20: =M20*N20*1000/1000000 -> 71.16276 | P20: =O20+H20 -> 501.60429 | Q20: =$P$18-P20 -> 1109.4938 | R20: =50/L20 -> 11.904762 | S20: =R20*Rough1!$B$25/1000000/1000 -> 3.0683478 | T20: =S20/C20*1000 -> 0.94040328 | U20: 75 | V20: =S20*U20/1000 -> 0.23012609 | W20: =V20/(Q20*Rough1!$B$26)*1000 -> 0.020741538 | X20: =V20/(I20*Rough1!$B$26)*1000 -> 0.0096244028 | Y20: 5 | Z20: =Y20*F20 -> 242.14758 | AA20: 0.15 | AB20: =AA20*M20 -> 85.395312 | AC20: =AB20+Z20 -> 327.54289 | AD20: =$AC$18-AC20 -> 578.79045 | AE20: =AC20/C20 -> 0.10038706 | AF20: =AC20/Q20 -> 0.2952183
A21: Best | B21: LDV (75-mile EV range) | C21: 3262.8 | D21: 711.79192 | E21: 18 | F21: =D21/E21 -> 39.543996 | G21: 8.888 | H21: =F21*G21 -> 351.46703 | I21: =C21-D21 -> 2551.0081 | J21: =I21/C21 -> 0.78184629 | K21: =J21-J20 -> 0.049019048 | L21: =L20 -> 4.2 | M21: =I21/L21 -> 607.38288 | N21: 125 | O21: =M21*N21*1000/1000000 -> 75.92286 | P21: =O21+H21 -> 427.38989 | Q21: =$P$18-P21 -> 1183.7082 | R21: =75/L21 -> 17.857143 | S21: =R21*Rough1!$B$25/1000000/1000 -> 4.6025217 | T21: =S21/C21*1000 -> 1.4106049 | U21: 75 | V21: =S21*U21/1000 -> 0.34518913 | W21: =V21/(Q21*Rough1!$B$26)*1000 -> 0.029161673 | X21: =V21/(I21*Rough1!$B$26)*1000 -> 0.013531479 | Y21: 5 | Z21: =Y21*F21 -> 197.71998 | AA21: 0.15 | AB21: =AA21*M21 -> 91.107431 | AC21: =AB21+Z21 -> 288.82741 | AD21: =$AC$18-AC21 -> 617.50592 | AE21: =AC21/C21 -> 0.088521334 | AF21: =AC21/Q21 -> 0.2440022
A22: Best | B22: LDV (100-mile EV range) | C22: 3262.8 | D22: 551.85257 | E22: 18 | F22: =D22/E22 -> 30.658476 | G22: 8.888 | H22: =F22*G22 -> 272.49254 | I22: =C22-D22 -> 2710.9474 | J22: =I22/C22 -> 0.83086534 | K22: =J22-J21 -> 0.049019048 | L22: =L21 -> 4.2 | M22: =I22/L22 -> 645.46367 | N22: 125 | O22: =M22*N22*1000/1000000 -> 80.682959 | P22: =O22+H22 -> 353.17549 | Q22: =$P$18-P22 -> 1257.9226 | R22: =100/L22 -> 23.809524 | S22: =R22*Rough1!$B$25/1000000/1000 -> 6.1366956 | T22: =S22/C22*1000 -> 1.8808066 | U22: 75 | V22: =S22*U22/1000 -> 0.46025217 | W22: =V22/(Q22*Rough1!$B$26)*1000 -> 0.036588273 | X22: =V22/(I22*Rough1!$B$26)*1000 -> 0.01697754 | Y22: 5 | Z22: =Y22*F22 -> 153.29238 | AA22: 0.15 | AB22: =AA22*M22 -> 96.819551 | AC22: =AB22+Z22 -> 250.11193 | AD22: =$AC$18-AC22 -> 656.2214 | AE22: =AC22/C22 -> 0.076655612 | AF22: =AC22/Q22 -> 0.19882934
A23: Best | B23: LDV (125-mile EV range) | C23: 3262.8 | D23: 491.22464 | E23: 18 | F23: =D23/E23 -> 27.290258 | G23: 8.888 | H23: =F23*G23 -> 242.55581 | I23: =C23-D23 -> 2771.5754 | J23: =I23/C23 -> 0.84944691 | K23: =J23-J22 -> 0.018581565 | L23: =L22 -> 4.2 | M23: =I23/L23 -> 659.8989 | N23: 125 | O23: =M23*N23*1000/1000000 -> 82.487362 | P23: =O23+H23 -> 325.04317 | Q23: =$P$18-P23 -> 1286.055 | R23: =125/L23 -> 29.761905 | S23: =R23*Rough1!$B$25/1000000/1000 -> 7.6708696 | T23: =S23/C23*1000 -> 2.3510082 | U23: 75 | V23: =S23*U23/1000 -> 0.57531522 | W23: =V23/(Q23*Rough1!$B$26)*1000 -> 0.044734886 | X23: =V23/(I23*Rough1!$B$26)*1000 -> 0.020757697 | Y23: 5 | Z23: =Y23*F23 -> 136.45129 | AA23: 0.15 | AB23: =AA23*M23 -> 98.984834 | AC23: =AB23+Z23 -> 235.43612 | AD23: =$AC$18-AC23 -> 670.89721 | AE23: =AC23/C23 -> 0.072157694 | AF23: =AC23/Q23 -> 0.18306848
A24: Best | B24: LDV (150-mile EV range) | C24: 3262.8 | D24: 430.59671 | E24: 18 | F24: =D24/E24 -> 23.922039 | G24: 8.888 | H24: =F24*G24 -> 212.61908 | I24: =C24-D24 -> 2832.2033 | J24: =I24/C24 -> 0.86802847 | K24: =J24-J23 -> 0.018581566 | L24: =L23 -> 4.2 | M24: =I24/L24 -> 674.33412 | N24: 125 | O24: =M24*N24*1000/1000000 -> 84.291765 | P24: =O24+H24 -> 296.91085 | Q24: =$P$18-P24 -> 1314.1873 | R24: =150/L24 -> 35.714286 | S24: =R24*Rough1!$B$25/1000000/1000 -> 9.2050435 | T24: =S24/C24*1000 -> 2.8212098 | U24: 75 | V24: =S24*U24/1000 -> 0.69037826 | W24: =V24/(Q24*Rough1!$B$26)*1000 -> 0.052532715 | X24: =V24/(I24*Rough1!$B$26)*1000 -> 0.024376014 | Y24: 5 | Z24: =Y24*F24 -> 119.6102 | AA24: 0.15 | AB24: =AA24*M24 -> 101.15012 | AC24: =AB24+Z24 -> 220.76031 | AD24: =$AC$18-AC24 -> 685.57302 | AE24: =AC24/C24 -> 0.067659775 | AF24: =AC24/Q24 -> 0.16798238
A25: Best | B25: EV | C25: 3262.8 | D25: =C25*0 -> 0 | E25: 18 | F25: =D25/E25 -> 0 | G25: 8.888 | H25: =F25*G25 -> 0 | I25: =C25-D25 -> 3262.8 | J25: =I25/C25 -> 1 | K25: =J25-J24 -> 0.13197153 | L25: =L24 -> 4.2 | M25: =I25/L25 -> 776.85714 | N25: 125 | O25: =M25*N25*1000/1000000 -> 97.107143 | P25: =O25+H25 -> 97.107143 | Q25: =$P$18-P25 -> 1513.991 | R25: =300/L25 -> 71.428571 | S25: =R25*Rough1!$B$25/1000000/1000 -> 18.410087 | T25: =S25/C25*1000 -> 5.6424197 | U25: 75 | V25: =S25*U25/1000 -> 1.3807565 | W25: =V25/(Q25*Rough1!$B$26)*1000 -> 0.091199784 | X25: =V25/(I25*Rough1!$B$26)*1000 -> 0.042318148 | Y25: 5 | Z25: =Y25*F25 -> 0 | AA25: 0.15 | AB25: =AA25*M25 -> 116.52857 | AC25: =AB25+Z25 -> 116.52857 | AD25: =$AC$18-AC25 -> 789.80476 | AE25: =AC25/C25 -> 0.035714286 | AF25: =AC25/Q25 -> 0.07696781
J52: =I10/C10 -> 0
I53: 25 | J53: =I11/C11 -> 0.59358504 | M53: =J53-J52 -> 0.59358504
I54: 50 | J54: =I12/C12 -> 0.73282724 | M54: =J54-J53 -> 0.13924221
I55: 75 | J55: =I13/C13 -> 0.78184629 | M55: =J55-J54 -> 0.049019048
I56: 100 | J56: =I14/C14 -> 0.83086534 | M56: =J56-J55 -> 0.049019048
I57: 125 | J57: =I15/C15 -> 0.84944691 | M57: =J57-J56 -> 0.018581565
I58: 150 | J58: =I16/C16 -> 0.86802847 | M58: =J58-J57 -> 0.018581566
J59: =I17/C17 -> 1 | M59: =J59-J58 -> 0.13197153
C77: Scenario | D77: Vehicle Type | E77: $ B OC Gas | F77: $B OC ELC | G77: $B OC Total
C78: Worst | D78: ICE | E78: 181.26667 | F78: 0 | G78: 181.26667
C79: Worst | D79: LDV (25-mile EV range) | E79: 73.669486 | F79: 267.13783 | G79: 340.80731
C80: Worst | D80: LDV (50-mile EV range) | E80: 48.429515 | F80: 329.80258 | G80: 378.2321
C81: Worst | D81: LDV (75-mile EV range) | E81: 39.543996 | F81: 351.86318 | G81: 391.40718
C82: Worst | D82: LDV (100-mile EV range) | E82: 30.658476 | F82: 373.92378 | G82: 404.58226
C83: Worst | D83: LDV (125-mile EV range) | E83: 27.290258 | F83: 382.28626 | G83: 409.57651
...

Sheet Subsectors_Emissions
B1: Ordered Subsectors | C1: Emissions B tons CO2
A2: 1 | B2: LDV | C2: =Rough1!J2 -> 1.1003897
A3: 2 | B3: EREV 100 mi (nat. avgs.) | C3: ='Calcs by Scenario'!P14/1000 -> 0.44784862
A4: 3 | B4: Combination Truck | C4: =Rough1!J5 -> 0.28776514
A5: 4 | B5: Non Transport Vehicles | C5: =Rough1!J17 -> 0.2193
A6: 5 | B6: SU Truck | C6: =Rough1!J4 -> 0.1755322
A7: 6 | B7: Aircraft | C7: =Rough1!J16 -> 0.1704
A8: 7 | B8: Pipeline | C8: =Rough1!J18 -> 0.0693
A9: 8 | B9: Watercraft | C9: =Rough1!J15 -> 0.0499
A10: 9 | B10: Rail | C10: =Rough1!J14 -> 0.0325
A11: 10 | B11: Buses | C11: =Rough1!J3 -> 0.025436878

Sheet Rough1
C1: Vehicles | D1: Average Miles | E1: VMT (B) | F1: Miles Per Gallon | G1: Gallons (B) | H1: Carbon Intensity (kg CO2 / gallon) | I1: Emissions (M tons CO2) | J1: Emissions B tons CO2
A2: 2022 | B2: LDV | C2: 257741217 | D2: 10952 | E2: =C2*D2/1000000000 -> 2822.7818 | F2: 22.8 | G2: =E2/F2 -> 123.80622 | H2: 8.888 | I2: =G2*H2 -> 1100.3897 | J2: =I2/1000 -> 1.1003897 | K2: LDV
A3: 2022 | B3: Buses | C3: 958055 | D3: 19300 | E3: =C3*D3/1000000000 -> 18.490461 | F3: 7.4 | G3: =E3/F3 -> 2.498711 | H3: 10.18 | I3: =G3*H3 -> 25.436878 | J3: =I3/1000 -> 0.025436878 | K3: Buses
A4: 2022 | B4: SU Truck | C4: 11049522 | D4: 12328 | E4: =C4*D4/1000000000 -> 136.21851 | F4: 7.9 | G4: =E4/F4 -> 17.242849 | H4: 10.18 | I4: =G4*H4 -> 175.5322 | J4: =I4/1000 -> 0.1755322 | K4: SU Truck
A5: 2022 | B5: Combination Truck | C5: 3239716 | D5: 60205 | E5: =C5*D5/1000000000 -> 195.0471 | F5: 6.9 | G5: =E5/F5 -> 28.267696 | H5: 10.18 | I5: =G5*H5 -> 287.76514 | J5: =I5/1000 -> 0.28776514 | K5: Combination Truck
A6: 2022 | B6: Rec Boats (Gas) | G6: 1.2 | H6: =I6/G6 -> 9 | I6: 10.8 | J6: =I6/1000 -> 0.0108 | K6: Rec Boats (Gas)
A7: 2022 | B7: Commercial Aviation | G7: 13.7 | H7: =I7/G7 -> 9.4671533 | I7: 129.7 | J7: =I7/1000 -> 0.1297 | K7: Commercial Aviation
A8: 2022 | B8: General Aviation | G8: 2.1 | H8: =I8/G8 -> 11.666667 | I8: 24.5 | J8: =I8/1000 -> 0.0245 | K8: General Aviation
A9: 2022 | B9: Military Aviation | G9: 1.1 | H9: =I9/G9 -> 12.090909 | I9: 13.3 | J9: =I9/1000 -> 0.0133 | K9: Military Aviation
A10: 2022 | B10: Aviation Fuel Aviation | G10: 0.2 | H10: =I10/G10 -> 7.5 | I10: 1.5 | J10: =I10/1000 -> 0.0015 | K10: Aviation Fuel Aviation
A11: 2022 | B11: Ships and Boats | G11: 2 | H11: =I11/G11 -> 11.45 | I11: 22.9 | J11: =I11/1000 -> 0.0229 | K11: Ships and Boats
A12: 2022 | B12: Rec Boats | G12: 0.3 | H12: =I12/G12 -> 10 | I12: 3 | J12: =I12/1000 -> 0.003 | K12: Rec Boats
A13: 2022 | B13: Other Diesel Boats | G13: 0.8 | H13: =I13/G13 -> 9.75 | I13: 7.8 | J13: =I13/1000 -> 0.0078 | K13: Other Diesel Boats
A14: 2022 | B14: Rail | G14: 3.2 | H14: =I14/G14 -> 10.15625 | I14: 32.5 | J14: =I14/1000 -> 0.0325 | K14: Rail
A15: 2022 | B15: All Watercraft | G15: =G6+G11+G12+G13 -> 4.3 | H15: =I15/G15 -> 11.604651 | I15: 49.9 | J15: =I15/1000 -> 0.0499 | K15: All Watercraft
A16: 2022 | B16: All Aircraft | G16: =G7+G8+G9+G10 -> 17.1 | H16: =I16/G16 -> 9.9649123 | I16: 170.4 | J16: =I16/1000 -> 0.1704 | K16: All Aircraft
A17: 2022 | B17: Non Transport Vehicles | I17: 219.3 | J17: =I17/1000 -> 0.2193 | K17: Non Transport Vehicles
A18: 2022 | B18: Pipelines | I18: 69.3 | J18: =I18/1000 -> 0.0693 | K18: Pipelines
A19: 2022 | B19: Lubricants | I19: 8.4 | J19: =I19/1000 -> 0.0084
A25: Vehicles | B25: 257741217
A26: Lifespan | B26: 10

Sheet Calcs by Charge
A1: Charge Freq | B1: Vehicle Type | C1: VMT | D1: Gas VMT (B) | E1: MPG | F1: Gallons (B) | G1: Carbon Intensity (kg CO2 / gallon) | H1: Gas Emissions (M tons CO2) | I1: Electric VMT (B) | J1: % Electric | K1: % Increase Change | L1: mi / kWh | M1: Electricity (TWh) | N1: Carbon Intensity g CO2 / kWh | O1: Electricity Emissions (M t CO2) | P1: Total Emissions (M t CO2) | Q1: CO2 Saved (M t CO2) | R1: Average Battery Size (kWh) | S1: Installed Battery (TWh) | T1: Installed Battery (Wh) / mile | U1: Cost / kWh | V1: $T Installed Battery | W1: $ CAPEX / kg CO2 | X1: $ CAPEX / EV Mile | Y1: $ / gallon | Z1: $ B OC Gas | AA1: $ / kWh | AB1: $B OC ELC | AC1: $B OC Total | AD1: $B ELC Savings | AE1: $ OC / VMT | AF1: $OC / kg CO2 | AG1: Scenario EV VMT | AH1: Electric VMT (B) | AI1: EV VMT Difference
A2: 7 | B2: LDV (25-mile EV range) | C2: 3392.497 | D2: 1378.76 | E2: 26.4 | F2: =D2/E2 -> 52.225758 | G2: 8.888 | H2: =F2*G2 -> 464.18253 | I2: =C2-D2 -> 2013.737 | J2: =I2/C2 -> 0.59358549 | L2: 3.6 | M2: =I2/L2 -> 559.37139 | N2: 348 | O2: =M2*N2*1000/1000000 -> 194.66124 | P2: =O2+H2 -> 658.84378 | Q2: ='Calcs by Scenario'!$P$10-P2 -> 439.63222 | R2: =25/L2 -> 6.9444444 | S2: =R2*Rough1!$B$25/1000000/1000 -> 1.7898696 | T2: =S2/C2*1000 -> 0.52759651 | U2: 115 | V2: =S2*U2/1000 -> 0.205835 | W2: =V2/(Q2*Rough1!$B$26)*1000 -> 0.046819816 | X2: =V2/(I2*Rough1!$B$26)*1000 -> 0.010221543 | Y2: 3 | Z2: =Y2*F2 -> 156.67727 | AA2: 0.25 | AB2: =AA2*M2 -> 139.84285 | AC2: =AB2+Z2 -> 296.52012 | AD2: ='Calcs by Scenario'!$AC$10-AC2 -> 74.252607 | AE2: =AC2/C2 -> 0.087404682 | AF2: N/A | AG2: 1936.7493 | AH2: 2013.737 | AI2: =AG2-AH2*($C$25/C2) -> -76.987743
A3: 7 | B3: LDV (50-mile EV range) | C3: 3392.497 | D3: 906.37801 | E3: 26.4 | F3: =D3/E3 -> 34.3325 | G3: 8.888 | H3: =F3*G3 -> 305.14726 | I3: =C3-D3 -> 2486.119 | J3: =I3/C3 -> 0.73282865 | K3: =J3-J2 -> 0.13924316 | L3: 3.6 | M3: =I3/L3 -> 690.58861 | N3: 348 | O3: =M3*N3*1000/1000000 -> 240.32484 | P3: =O3+H3 -> 545.4721 | Q3: ='Calcs by Scenario'!$P$10-P3 -> 553.0039 | R3: =50/L3 -> 13.888889 | S3: =R3*Rough1!$B$25/1000000/1000 -> 3.5797391 | T3: =S3/C3*1000 -> 1.055193 | U3: =U2 -> 115 | V3: =S3*U3/1000 -> 0.41167 | W3: =V3/(Q3*Rough1!$B$26)*1000 -> 0.074442513 | X3: =V3/(I3*Rough1!$B$26)*1000 -> 0.016558741 | Y3: 3 | Z3: =Y3*F3 -> 102.9975 | AA3: 0.25 | AB3: =AA3*M3 -> 172.64715 | AC3: =AB3+Z3 -> 275.64465 | AD3: ='Calcs by Scenario'!$AC$10-AC3 -> 95.128074 | AE3: =AC3/C3 -> 0.081251259 | AF3: =AC3/Q3 -> 0.49844974 | AG3: 2391.0687 | AH3: 2486.119 | AI3: =AG3-AH3*($C$25/C3) -> -95.05026
A4: 7 | B4: LDV (75-mile EV range) | C4: 3392.497 | D4: 740.08144 | E4: 26.4 | F4: =D4/E4 -> 28.033388 | G4: 8.888 | H4: =F4*G4 -> 249.16075 | I4: =C4-D4 -> 2652.4156 | J4: =I4/C4 -> 0.78184758 | K4: =J4-J3 -> 0.049018929 | L4: 3.6 | M4: =I4/L4 -> 736.7821 | N4: 348 | O4: =M4*N4*1000/1000000 -> 256.40017 | P4: =O4+H4 -> 505.56092 | Q4: ='Calcs by Scenario'!$P$10-P4 -> 592.91508 | R4: =75/L4 -> 20.833333 | S4: =R4*Rough1!$B$25/1000000/1000 -> 5.3696087 | T4: =S4/C4*1000 -> 1.5827895 | U4: =U3 -> 115 | V4: =S4*U4/1000 -> 0.617505 | W4: =V4/(Q4*Rough1!$B$26)*1000 -> 0.10414729 | X4: =V4/(I4*Rough1!$B$26)*1000 -> 0.023280854 | Y4: 3 | Z4: =Y4*F4 -> 84.100164 | AA4: 0.25 | AB4: =AA4*M4 -> 184.19552 | AC4: =AB4+Z4 -> 268.29569 | AD4: ='Calcs by Scenario'!$AC$10-AC4 -> 102.47704 | AE4: =AC4/C4 -> 0.079085019 | AF4: =AC4/Q4 -> 0.45250273 | AG4: 2551.0081 | AH4: 2652.4156 | AI4: =AG4-AH4*($C$25/C4) -> -101.40748
A5: 7 | B5: LDV (100-mile EV range) | C5: 3392.497 | D5: 573.78487 | E5: 26.4 | F5: =D5/E5 -> 21.734275 | G5: 8.888 | H5: =F5*G5 -> 193.17424 | I5: =C5-D5 -> 2818.7121 | J5: =I5/C5 -> 0.83086651 | K5: =J5-J4 -> 0.049018929 | L5: 3.6 | M5: =I5/L5 -> 782.97559 | N5: 348 | O5: =M5*N5*1000/1000000 -> 272.47551 | P5: =O5+H5 -> 465.64975 | Q5: ='Calcs by Scenario'!$P$10-P5 -> 632.82625 | R5: =100/L5 -> 27.777778 | S5: =R5*Rough1!$B$25/1000000/1000 -> 7.1594783 | T5: =S5/C5*1000 -> 2.110386 | U5: =U4 -> 115 | V5: =S5*U5/1000 -> 0.82334 | W5: =V5/(Q5*Rough1!$B$26)*1000 -> 0.13010522 | X5: =V5/(I5*Rough1!$B$26)*1000 -> 0.029209794 | Y5: 3 | Z5: =Y5*F5 -> 65.202826 | AA5: 0.25 | AB5: =AA5*M5 -> 195.7439 | AC5: =AB5+Z5 -> 260.94672 | AD5: ='Calcs by Scenario'!$AC$10-AC5 -> 109.826 | AE5: =AC5/C5 -> 0.076918778 | AF5: =AC5/Q5 -> 0.41235129 | AG5: 2710.9474 | AH5: 2818.7121 | AI5: =AG5-AH5*($C$25/C5) -> -107.7647
A6: 7 | B6: LDV (125-mile EV range) | C6: 3392.497 | D6: 510.74716 | E6: 26.4 | F6: =D6/E6 -> 19.346483 | G6: 8.888 | H6: =F6*G6 -> 171.95154 | I6: =C6-D6 -> 2881.7498 | J6: =I6/C6 -> 0.84944801 | K6: =J6-J5 -> 0.018581508 | L6: 3.6 | M6: =I6/L6 -> 800.48607 | N6: 348 | O6: =M6*N6*1000/1000000 -> 278.56915 | P6: =O6+H6 -> 450.5207 | Q6: ='Calcs by Scenario'!$P$10-P6 -> 647.9553 | R6: =125/L6 -> 34.722222 | S6: =R6*Rough1!$B$25/1000000/1000 -> 8.9493478 | T6: =S6/C6*1000 -> 2.6379825 | U6: =U5 -> 115 | V6: =S6*U6/1000 -> 1.029175 | W6: =V6/(Q6*Rough1!$B$26)*1000 -> 0.15883426 | X6: =V6/(I6*Rough1!$B$26)*1000 -> 0.035713544 | Y6: 3 | Z6: =Y6*F6 -> 58.03945 | AA6: 0.25 | AB6: =AA6*M6 -> 200.12152 | AC6: =AB6+Z6 -> 258.16097 | AD6: ='Calcs by Scenario'!$AC$10-AC6 -> 112.61176 | AE6: =AC6/C6 -> 0.076097626 | AF6: =AC6/Q6 -> 0.39842404 | AG6: 2771.5754 | AH6: 2881.7498 | AI6: =AG6-AH6*($C$25/C6) -> -110.17447
A7: 7 | B7: LDV (150-mile EV range) | C7: 3392.497 | D7: 447.70945 | E7: 26.4 | F7: =D7/E7 -> 16.958691 | G7: 8.888 | H7: =F7*G7 -> 150.72885 | I7: =C7-D7 -> 2944.7875 | J7: =I7/C7 -> 0.86802952 | K7: =J7-J6 -> 0.018581508 | L7: 3.6 | M7: =I7/L7 -> 817.99654 | N7: 348 | O7: =M7*N7*1000/1000000 -> 284.6628 | P7: =O7+H7 -> 435.39165 | Q7: ='Calcs by Scenario'!$P$10-P7 -> 663.08435 | R7: =150/L7 -> 41.666667 | S7: =R7*Rough1!$B$25/1000000/1000 -> 10.739217 | T7: =S7/C7*1000 -> 3.165579 | U7: =U6 -> 115 | V7: =S7*U7/1000 -> 1.23501 | W7: =V7/(Q7*Rough1!$B$26)*1000 -> 0.18625232 | X7: =V7/(I7*Rough1!$B$26)*1000 -> 0.041938849 | Y7: 3 | Z7: =Y7*F7 -> 50.876074 | AA7: 0.25 | AB7: =AA7*M7 -> 204.49914 | AC7: =AB7+Z7 -> 255.37521 | AD7: ='Calcs by Scenario'!$AC$10-AC7 -> 115.39752 | AE7: =AC7/C7 -> 0.075276473 | AF7: =AC7/Q7 -> 0.38513231 | AG7: 2832.2033 | AH7: 2944.7875 | AI7: =AG7-AH7*($C$25/C7) -> -112.58425
A8: 5 | B8: LDV (25-mile EV range) | C8: 3392.497 | D8: 1671.3649 | E8: 26.4 | F8: =D8/E8 -> 63.309276 | G8: 8.888 | H8: =F8*G8 -> 562.69285 | I8: =C8-D8 -> 1721.1321 | J8: =I8/C8 -> 0.50733489 | L8: 3.6 | M8: =I8/L8 -> 478.09225 | N8: 348 | O8: =M8*N8*1000/1000000 -> 166.3761 | P8: =O8+H8 -> 729.06895 | Q8: ='Calcs by Scenario'!$P$10-P8 -> 369.40705 | R8: =25/L8 -> 6.9444444 | S8: =R8*Rough1!$B$25/1000000/1000 -> 1.7898696 | T8: =S8/C8*1000 -> 0.52759651 | U8: =U7 -> 115 | V8: =S8*U8/1000 -> 0.205835 | W8: =V8/(Q8*Rough1!$B$26)*1000 -> 0.055720377 | X8: =V8/(I8*Rough1!$B$26)*1000 -> 0.01195928 | Y8: 3 | Z8: =Y8*F8 -> 189.92783 | AA8: 0.25 | AB8: =AA8*M8 -> 119.52306 | AC8: =AB8+Z8 -> 309.45089 | AD8: ='Calcs by Scenario'!$AC$10-AC8 -> 61.321836 | AE8: =AC8/C8 -> 0.091216261 | AF8: =AC8/Q8 -> 0.83769623 | AG8: 1936.7493 | AH8: 1721.1321 | AI8: =AG8-AH8*($C$25/C8) -> 215.61715
A9: 5 | B9: LDV (50-mile EV range) | C9: 3392.497 | D9: 1260.3845 | E9: 26.4 | F9: =D9/E9 -> 47.741839 | G9: 8.888 | H9: =F9*G9 -> 424.32946 | I9: =C9-D9 -> 2132.1125 | J9: =I9/C9 -> 0.6284788 | K9: =J9-J8 -> 0.12114391 | L9: 3.6 | M9: =I9/L9 -> 592.25346 | N9: 348 | O9: =M9*N9*1000/1000000 -> 206.1042 | P9: =O9+H9 -> 630.43367 | Q9: ='Calcs by Scenario'!$P$10-P9 -> 468.04233 | R9: =50/L9 -> 13.888889 | S9: =R9*Rough1!$B$25/1000000/1000 -> 3.5797391 | T9: =S9/C9*1000 -> 1.055193 | U9: =U8 -> 115 | V9: =S9*U9/1000 -> 0.41167 | W9: =V9/(Q9*Rough1!$B$26)*1000 -> 0.087955719 | X9: =V9/(I9*Rough1!$B$26)*1000 -> 0.019308081 | Y9: 3 | Z9: =Y9*F9 -> 143.22552 | AA9: 0.25 | AB9: =AA9*M9 -> 148.06336 | AC9: =AB9+Z9 -> 291.28888 | AD9: ='Calcs by Scenario'!$AC$10-AC9 -> 79.483846 | AE9: =AC9/C9 -> 0.085862679 | AF9: =AC9/Q9 -> 0.62235585 | AG9: 2391.0687 | AH9: 2132.1125 | AI9: =AG9-AH9*($C$25/C9) -> 258.95628
A10: 5 | B10: LDV (75-mile EV range) | C10: 3392.497 | D10: 1109.5768 | E10: 26.4 | F10: =D10/E10 -> 42.029424 | G10: 8.888 | H10: =F10*G10 -> 373.55752 | I10: =C10-D10 -> 2282.9202 | J10: =I10/C10 -> 0.67293212 | K10: =J10-J9 -> 0.044453316 | L10: 3.6 | M10: =I10/L10 -> 634.1445 | N10: 348 | O10: =M10*N10*1000/1000000 -> 220.68229 | P10: =O10+H10 -> 594.23981 | Q10: ='Calcs by Scenario'!$P$10-P10 -> 504.23619 | R10: =75/L10 -> 20.833333 | S10: =R10*Rough1!$B$25/1000000/1000 -> 5.3696087 | T10: =S10/C10*1000 -> 1.5827895 | U10: =U9 -> 115 | V10: =S10*U10/1000 -> 0.617505 | W10: =V10/(Q10*Rough1!$B$26)*1000 -> 0.12246344 | X10: =V10/(I10*Rough1!$B$26)*1000 -> 0.027048909 | Y10: 3 | Z10: =Y10*F10 -> 126.08827 | AA10: 0.25 | AB10: =AA10*M10 -> 158.53612 | AC10: =AB10+Z10 -> 284.6244 | AD10: ='Calcs by Scenario'!$AC$10-AC10 -> 86.148329 | AE10: =AC10/C10 -> 0.083898202 | AF10: =AC10/Q10 -> 0.56446642 | AG10: 2551.0081 | AH10: 2282.9202 | AI10: =AG10-AH10*($C$25/C10) -> 268.08789
A11: 5 | B11: LDV (100-mile EV range) | C11: 3392.497 | D11: 958.76907 | E11: 26.4 | F11: =D11/E11 -> 36.31701 | G11: 8.888 | H11: =F11*G11 -> 322.78559 | I11: =C11-D11 -> 2433.7279 | J11: =I11/C11 -> 0.71738543 | K11: =J11-J10 -> 0.044453316 | L11: 3.6 | M11: =I11/L11 -> 676.03554 | N11: 348 | O11: =M11*N11*1000/1000000 -> 235.26037 | P11: =O11+H11 -> 558.04595 | Q11: ='Calcs by Scenario'!$P$10-P11 -> 540.43005 | R11: =100/L11 -> 27.777778 | S11: =R11*Rough1!$B$25/1000000/1000 -> 7.1594783 | T11: =S11/C11*1000 -> 2.110386 | U11: =U10 -> 115 | V11: =S11*U11/1000 -> 0.82334 | W11: =V11/(Q11*Rough1!$B$26)*1000 -> 0.15234904 | X11: =V11/(I11*Rough1!$B$26)*1000 -> 0.033830404 | Y11: 3 | Z11: =Y11*F11 -> 108.95103 | AA11: 0.25 | AB11: =AA11*M11 -> 169.00888 | AC11: =AB11+Z11 -> 277.95991 | AD11: ='Calcs by Scenario'!$AC$10-AC11 -> 92.812813 | AE11: =AC11/C11 -> 0.081933724 | AF11: =AC11/Q11 -> 0.51433098 | AG11: 2710.9474 | AH11: 2433.7279 | AI11: =AG11-AH11*($C$25/C11) -> 277.2195
A12: 5 | B12: LDV (125-mile EV range) | C12: 3392.497 | D12: 895.73136 | E12: 26.4 | F12: =D12/E12 -> 33.929218 | G12: 8.888 | H12: =F12*G12 -> 301.56289 | I12: =C12-D12 -> 2496.7656 | J12: =I12/C12 -> 0.73596694 | K12: =J12-J11 -> 0.018581508 | L12: 3.6 | M12: =I12/L12 -> 693.54601 | N12: 348 | O12: =M12*N12*1000/1000000 -> 241.35401 | P12: =O12+H12 -> 542.9169 | Q12: ='Calcs by Scenario'!$P$10-P12 -> 555.5591 | R12: =125/L12 -> 34.722222 | S12: =R12*Rough1!$B$25/1000000/1000 -> 8.9493478 | T12: =S12/C12*1000 -> 2.6379825 | U12: =U11 -> 115 | V12: =S12*U12/1000 -> 1.029175 | W12: =V12/(Q12*Rough1!$B$26)*1000 -> 0.18525032 | X12: =V12/(I12*Rough1!$B$26)*1000 -> 0.041220328 | Y12: 3 | Z12: =Y12*F12 -> 101.78765 | AA12: 0.25 | AB12: =AA12*M12 -> 173.3865 | AC12: =AB12+Z12 -> 275.17416 | AD12: ='Calcs by Scenario'!$AC$10-AC12 -> 95.59857 | AE12: =AC12/C12 -> 0.081112572 | AF12: =AC12/Q12 -> 0.49531032 | AG12: 2771.5754 | AH12: 2496.7656 | AI12: =AG12-AH12*($C$25/C12) -> 274.80972
A13: 5 | B13: LDV (150-mile EV range) | C13: 3392.497 | D13: 832.69365 | E13: 26.4 | F13: =D13/E13 -> 31.541426 | G13: 8.888 | H13: =F13*G13 -> 280.34019 | I13: =C13-D13 -> 2559.8034 | J13: =I13/C13 -> 0.75454845 | K13: =J13-J12 -> 0.018581508 | L13: 3.6 | M13: =I13/L13 -> 711.05649 | N13: 348 | O13: =M13*N13*1000/1000000 -> 247.44766 | P13: =O13+H13 -> 527.78785 | Q13: ='Calcs by Scenario'!$P$10-P13 -> 570.68815 | R13: =150/L13 -> 41.666667 | S13: =R13*Rough1!$B$25/1000000/1000 -> 10.739217 | T13: =S13/C13*1000 -> 3.165579 | U13: =U12 -> 115 | V13: =S13*U13/1000 -> 1.23501 | W13: =V13/(Q13*Rough1!$B$26)*1000 -> 0.21640716 | X13: =V13/(I13*Rough1!$B$26)*1000 -> 0.048246284 | Y13: 3 | Z13: =Y13*F13 -> 94.624278 | AA13: 0.25 | AB13: =AA13*M13 -> 177.76412 | AC13: =AB13+Z13 -> 272.3884 | AD13: ='Calcs by Scenario'!$AC$10-AC13 -> 98.384327 | AE13: =AC13/C13 -> 0.08029142 | AF13: =AC13/Q13 -> 0.47729815 | AG13: 2832.2033 | AH13: 2559.8034 | AI13: =AG13-AH13*($C$25/C13) -> 272.39994
A14: 3 | B14: LDV (25-mile EV range) | C14: 3392.497 | D14: 1963.9698 | E14: 26.4 | F14: =D14/E14 -> 74.392795 | G14: 8.888 | H14: =F14*G14 -> 661.20316 | I14: =C14-D14 -> 1428.5272 | J14: =I14/C14 -> 0.4210843 | L14: 3.6 | M14: =I14/L14 -> 396.81311 | N14: 348 | O14: =M14*N14*1000/1000000 -> 138.09096 | P14: =O14+H14 -> 799.29413 | Q14: ='Calcs by Scenario'!$P$10-P14 -> 299.18187 | R14: =25/L14 -> 6.9444444 | S14: =R14*Rough1!$B$25/1000000/1000 -> 1.7898696 | T14: =S14/C14*1000 -> 0.52759651 | U14: =U13 -> 115 | V14: =S14*U14/1000 -> 0.205835 | W14: =V14/(Q14*Rough1!$B$26)*1000 -> 0.068799288 | X14: =V14/(I14*Rough1!$B$26)*1000 -> 0.014408896 | Y14: 3 | Z14: =Y14*F14 -> 223.17838 | AA14: 0.25 | AB14: =AA14*M14 -> 99.203279 | AC14: =AB14+Z14 -> 322.38166 | AD14: ='Calcs by Scenario'!$AC$10-AC14 -> 48.391064 | AE14: =AC14/C14 -> 0.09502784 | AF14: =AC14/Q14 -> 1.0775441 | AG14: 1936.7493 | AH14: 1428.5272 | AI14: =AG14-AH14*($C$25/C14) -> 508.22204
A15: 3 | B15: LDV (50-mile EV range) | C15: 3392.497 | D15: 1614.3911 | E15: 26.4 | F15: =D15/E15 -> 61.151177 | G15: 8.888 | H15: =F15*G15 -> 543.51166 | I15: =C15-D15 -> 1778.1059 | J15: =I15/C15 -> 0.52412896 | K15: =J15-J14 -> 0.10304466 | L15: 3.6 | M15: =I15/L15 -> 493.91831 | N15: 348 | O15: =M15*N15*1000/1000000 -> 171.88357 | P15: =O15+H15 -> 715.39524 | Q15: ='Calcs by Scenario'!$P$10-P15 -> 383.08076 | R15: =50/L15 -> 13.888889 | S15: =R15*Rough1!$B$25/1000000/1000 -> 3.5797391 | T15: =S15/C15*1000 -> 1.055193 | U15: =U14 -> 115 | V15: =S15*U15/1000 -> 0.41167 | W15: =V15/(Q15*Rough1!$B$26)*1000 -> 0.10746298 | X15: =V15/(I15*Rough1!$B$26)*1000 -> 0.023152164 | Y15: 3 | Z15: =Y15*F15 -> 183.45353 | AA15: 0.25 | AB15: =AA15*M15 -> 123.47958 | AC15: =AB15+Z15 -> 306.93311 | AD15: ='Calcs by Scenario'!$AC$10-AC15 -> 63.839618 | AE15: =AC15/C15 -> 0.090474099 | AF15: =AC15/Q15 -> 0.80122298 | AG15: 2391.0687 | AH15: 1778.1059 | AI15: =AG15-AH15*($C$25/C15) -> 612.96281
A16: 3 | B16: LDV (75-mile EV range) | C16: 3392.497 | D16: 1479.0722 | E16: 26.4 | F16: =D16/E16 -> 56.025461 | G16: 8.888 | H16: =F16*G16 -> 497.9543 | I16: =C16-D16 -> 1913.4248 | J16: =I16/C16 -> 0.56401666 | K16: =J16-J15 -> 0.039887702 | L16: 3.6 | M16: =I16/L16 -> 531.5069 | N16: 348 | O16: =M16*N16*1000/1000000 -> 184.9644 | P16: =O16+H16 -> 682.9187 | Q16: ='Calcs by Scenario'!$P$10-P16 -> 415.5573 | R16: =75/L16 -> 20.833333 | S16: =R16*Rough1!$B$25/1000000/1000 -> 5.3696087 | T16: =S16/C16*1000 -> 1.5827895 | U16: =U15 -> 115 | V16: =S16*U16/1000 -> 0.617505 | W16: =V16/(Q16*Rough1!$B$26)*1000 -> 0.14859684 | X16: =V16/(I16*Rough1!$B$26)*1000 -> 0.032272237 | Y16: 3 | Z16: =Y16*F16 -> 168.07638 | AA16: 0.25 | AB16: =AA16*M16 -> 132.87672 | AC16: =AB16+Z16 -> 300.95311 | AD16: ='Calcs by Scenario'!$AC$10-AC16 -> 69.81962 | AE16: =AC16/C16 -> 0.088711385 | AF16: =AC16/Q16 -> 0.72421566 | AG16: 2551.0081 | AH16: 1913.4248 | AI16: =AG16-AH16*($C$25/C16) -> 637.58325
A17: 3 | B17: LDV (100-mile EV range) | C17: 3392.497 | D17: 1343.7533 | E17: 26.4 | F17: =D17/E17 -> 50.899745 | G17: 8.888 | H17: =F17*G17 -> 452.39693 | I17: =C17-D17 -> 2048.7437 | J17: =I17/C17 -> 0.60390436 | K17: =J17-J16 -> 0.039887702 | L17: 3.6 | M17: =I17/L17 -> 569.09548 | N17: 348 | O17: =M17*N17*1000/1000000 -> 198.04523 | P17: =O17+H17 -> 650.44216 | Q17: ='Calcs by Scenario'!$P$10-P17 -> 448.03384 | R17: =100/L17 -> 27.777778 | S17: =R17*Rough1!$B$25/1000000/1000 -> 7.1594783 | T17: =S17/C17*1000 -> 2.110386 | U17: =U16 -> 115 | V17: =S17*U17/1000 -> 0.82334 | W17: =V17/(Q17*Rough1!$B$26)*1000 -> 0.18376737 | X17: =V17/(I17*Rough1!$B$26)*1000 -> 0.040187554 | Y17: 3 | Z17: =Y17*F17 -> 152.69923 | AA17: 0.25 | AB17: =AA17*M17 -> 142.27387 | AC17: =AB17+Z17 -> 294.9731 | AD17: ='Calcs by Scenario'!$AC$10-AC17 -> 75.799622 | AE17: =AC17/C17 -> 0.086948671 | AF17: =AC17/Q17 -> 0.65837238 | AG17: 2710.9474 | AH17: 2048.7437 | AI17: =AG17-AH17*($C$25/C17) -> 662.20369
A18: 3 | B18: LDV (125-mile EV range) | C18: 3392.497 | D18: 1280.7156 | E18: 26.4 | F18: =D18/E18 -> 48.511953 | G18: 8.888 | H18: =F18*G18 -> 431.17424 | I18: =C18-D18 -> 2111.7814 | J18: =I18/C18 -> 0.62248587 | K18: =J18-J17 -> 0.018581508 | L18: 3.6 | M18: =I18/L18 -> 586.60596 | N18: 348 | O18: =M18*N18*1000/1000000 -> 204.13887 | P18: =O18+H18 -> 635.31311 | Q18: ='Calcs by Scenario'!$P$10-P18 -> 463.16289 | R18: =125/L18 -> 34.722222 | S18: =R18*Rough1!$B$25/1000000/1000 -> 8.9493478 | T18: =S18/C18*1000 -> 2.6379825 | U18: =U17 -> 115 | V18: =S18*U18/1000 -> 1.029175 | W18: =V18/(Q18*Rough1!$B$26)*1000 -> 0.22220584 | X18: =V18/(I18*Rough1!$B$26)*1000 -> 0.04873492 | Y18: 3 | Z18: =Y18*F18 -> 145.53586 | AA18: 0.25 | AB18: =AA18*M18 -> 146.65149 | AC18: =AB18+Z18 -> 292.18735 | AD18: ='Calcs by Scenario'!$AC$10-AC18 -> 78.58538 | AE18: =AC18/C18 -> 0.086127518 | AF18: =AC18/Q18 -> 0.63085224 | AG18: 2771.5754 | AH18: 2111.7814 | AI18: =AG18-AH18*($C$25/C18) -> 659.79391
A19: 3 | B19: LDV (150-mile EV range) | C19: 3392.497 | D19: 1217.6778 | E19: 26.4 | F19: =D19/E19 -> 46.124161 | G19: 8.888 | H19: =F19*G19 -> 409.95154 | I19: =C19-D19 -> 2174.8192 | J19: =I19/C19 -> 0.64106738 | K19: =J19-J18 -> 0.018581508 | L19: 3.6 | M19: =I19/L19 -> 604.11643 | N19: 348 | O19: =M19*N19*1000/1000000 -> 210.23252 | P19: =O19+H19 -> 620.18406 | Q19: ='Calcs by Scenario'!$P$10-P19 -> 478.29194 | R19: =150/L19 -> 41.666667 | S19: =R19*Rough1!$B$25/1000000/1000 -> 10.739217 | T19: =S19/C19*1000 -> 3.165579 | U19: =U18 -> 115 | V19: =S19*U19/1000 -> 1.23501 | W19: =V19/(Q19*Rough1!$B$26)*1000 -> 0.25821259 | X19: =V19/(I19*Rough1!$B$26)*1000 -> 0.05678679 | Y19: 3 | Z19: =Y19*F19 -> 138.37248 | AA19: 0.25 | AB19: =AA19*M19 -> 151.02911 | AC19: =AB19+Z19 -> 289.40159 | AD19: ='Calcs by Scenario'!$AC$10-AC19 -> 81.371137 | AE19: =AC19/C19 -> 0.085306366 | AF19: =AC19/Q19 -> 0.60507311 | AG19: 2832.2033 | AH19: 2174.8192 | AI19: =AG19-AH19*($C$25/C19) -> 657.38414
A20: 2 | B20: LDV (25-mile EV range) | C20: 3392.497 | D20: 2159.0397 | E20: 26.4 | F20: =D20/E20 -> 81.781807 | G20: 8.888 | H20: =F20*G20 -> 726.8767 | I20: =C20-D20 -> 1233.4573 | J20: =I20/C20 -> 0.3635839 | L20: 3.6 | M20: =I20/L20 -> 342.62702 | N20: 348 | O20: =M20*N20*1000/1000000 -> 119.2342 | P20: =O20+H20 -> 846.11091 | Q20: ='Calcs by Scenario'!$P$10-P20 -> 252.36509 | R20: =25/L20 -> 6.9444444 | S20: =R20*Rough1!$B$25/1000000/1000 -> 1.7898696 | T20: =S20/C20*1000 -> 0.52759651 | U20: =U19 -> 115 | V20: =S20*U20/1000 -> 0.205835 | W20: =V20/(Q20*Rough1!$B$26)*1000 -> 0.08156239 | X20: =V20/(I20*Rough1!$B$26)*1000 -> 0.016687647 | Y20: 3 | Z20: =Y20*F20 -> 245.34542 | AA20: 0.25 | AB20: =AA20*M20 -> 85.656756 | AC20: =AB20+Z20 -> 331.00218 | AD20: ='Calcs by Scenario'!$AC$10-AC20 -> 39.770549 | AE20: =AC20/C20 -> 0.097568893 | AF20: =AC20/Q20 -> 1.3116005 | AG20: 1936.7493 | AH20: 1233.4573 | AI20: =AG20-AH20*($C$25/C20) -> 703.29197
A21: 2 | B21: LDV (50-mile EV range) | C21: 3392.497 | D21: 1850.3954 | E21: 26.4 | F21: =D21/E21 -> 70.090736 | G21: 8.888 | H21: =F21*G21 -> 622.96646 | I21: =C21-D21 -> 1542.1016 | J21: =I21/C21 -> 0.4545624 | K21: =J21-J20 -> 0.090978497 | L21: 3.6 | M21: =I21/L21 -> 428.36154 | N21: 348 | O21: =M21*N21*1000/1000000 -> 149.06982 | P21: =O21+H21 -> 772.03628 | Q21: ='Calcs by Scenario'!$P$10-P21 -> 326.43972 | R21: =50/L21 -> 13.888889 | S21: =R21*Rough1!$B$25/1000000/1000 -> 3.5797391 | T21: =S21/C21*1000 -> 1.055193 | U21: =U20 -> 115 | V21: =S21*U21/1000 -> 0.41167 | W21: =V21/(Q21*Rough1!$B$26)*1000 -> 0.12610904 | X21: =V21/(I21*Rough1!$B$26)*1000 -> 0.026695388 | Y21: 3 | Z21: =Y21*F21 -> 210.27221 | AA21: 0.25 | AB21: =AA21*M21 -> 107.09039 | AC21: =AB21+Z21 -> 317.3626 | AD21: ='Calcs by Scenario'!$AC$10-AC21 -> 53.410132 | AE21: =AC21/C21 -> 0.093548379 | AF21: =AC21/Q21 -> 0.97219357 | AG21: 2391.0687 | AH21: 1542.1016 | AI21: =AG21-AH21*($C$25/C21) -> 848.96717
A22: 2 | B22: LDV (75-mile EV range) | C22: 3392.497 | D22: 1725.4024 | E22: 26.4 | F22: =D22/E22 -> 65.356152 | G22: 8.888 | H22: =F22*G22 -> 580.88548 | I22: =C22-D22 -> 1667.0946 | J22: =I22/C22 -> 0.49140636 | K22: =J22-J21 -> 0.03684396 | L22: 3.6 | M22: =I22/L22 -> 463.08183 | N22: 348 | O22: =M22*N22*1000/1000000 -> 161.15248 | P22: =O22+H22 -> 742.03796 | Q22: ='Calcs by Scenario'!$P$10-P22 -> 356.43804 | R22: =75/L22 -> 20.833333 | S22: =R22*Rough1!$B$25/1000000/1000 -> 5.3696087 | T22: =S22/C22*1000 -> 1.5827895 | U22: =U21 -> 115 | V22: =S22*U22/1000 -> 0.617505 | W22: =V22/(Q22*Rough1!$B$26)*1000 -> 0.17324329 | X22: =V22/(I22*Rough1!$B$26)*1000 -> 0.03704079 | Y22: 3 | Z22: =Y22*F22 -> 196.06846 | AA22: 0.25 | AB22: =AA22*M22 -> 115.77046 | AC22: =AB22+Z22 -> 311.83891 | AD22: ='Calcs by Scenario'!$AC$10-AC22 -> 58.933814 | AE22: =AC22/C22 -> 0.091920174 | AF22: =AC22/Q22 -> 0.8748755 | AG22: 2551.0081 | AH22: 1667.0946 | AI22: =AG22-AH22*($C$25/C22) -> 883.91349
A23: 2 | B23: LDV (100-mile EV range) | C23: 3392.497 | D23: 1600.4094 | E23: 26.4 | F23: =D23/E23 -> 60.621568 | G23: 8.888 | H23: =F23*G23 -> 538.80449 | I23: =C23-D23 -> 1792.0876 | J23: =I23/C23 -> 0.52825032 | K23: =J23-J22 -> 0.03684396 | L23: 3.6 | M23: =I23/L23 -> 497.80211 | N23: 348 | O23: =M23*N23*1000/1000000 -> 173.23514 | P23: =O23+H23 -> 712.03963 | Q23: ='Calcs by Scenario'!$P$10-P23 -> 386.43637 | R23: =100/L23 -> 27.777778 | S23: =R23*Rough1!$B$25/1000000/1000 -> 7.1594783 | T23: =S23/C23*1000 -> 2.110386 | U23: =U22 -> 115 | V23: =S23*U23/1000 -> 0.82334 | W23: =V23/(Q23*Rough1!$B$26)*1000 -> 0.21305966 | X23: =V23/(I23*Rough1!$B$26)*1000 -> 0.045943066 | Y23: 3 | Z23: =Y23*F23 -> 181.8647 | AA23: 0.25 | AB23: =AA23*M23 -> 124.45053 | AC23: =AB23+Z23 -> 306.31523 | AD23: ='Calcs by Scenario'!$AC$10-AC23 -> 64.457495 | AE23: =AC23/C23 -> 0.090291968 | AF23: =AC23/Q23 -> 0.79266667 | AG23: 2710.9474 | AH23: 1792.0876 | AI23: =AG23-AH23*($C$25/C23) -> 918.85982
A24: 2 | B24: LDV (125-mile EV range) | C24: 3392.497 | D24: 1537.3717 | E24: 26.4 | F24: =D24/E24 -> 58.233776 | G24: 8.888 | H24: =F24*G24 -> 517.5818 | I24: =C24-D24 -> 1855.1253 | J24: =I24/C24 -> 0.54683182 | K24: =J24-J23 -> 0.018581508 | L24: 3.6 | M24: =I24/L24 -> 515.31259 | N24: 348 | O24: =M24*N24*1000/1000000 -> 179.32878 | P24: =O24+H24 -> 696.91058 | Q24: ='Calcs by Scenario'!$P$10-P24 -> 401.56542 | R24: =125/L24 -> 34.722222 | S24: =R24*Rough1!$B$25/1000000/1000 -> 8.9493478 | T24: =S24/C24*1000 -> 2.6379825 | U24: =U23 -> 115 | V24: =S24*U24/1000 -> 1.029175 | W24: =V24/(Q24*Rough1!$B$26)*1000 -> 0.25629074 | X24: =V24/(I24*Rough1!$B$26)*1000 -> 0.055477384 | Y24: 3 | Z24: =Y24*F24 -> 174.70133 | AA24: 0.25 | AB24: =AA24*M24 -> 128.82815 | AC24: =AB24+Z24 -> 303.52947 | AD24: ='Calcs by Scenario'!$AC$10-AC24 -> 67.243253 | AE24: =AC24/C24 -> 0.089470816 | AF24: =AC24/Q24 -> 0.75586557 | AG24: 2771.5754 | AH24: 1855.1253 | AI24: =AG24-AH24*($C$25/C24) -> 916.45004
A25: 2 | B25: LDV (150-mile EV range) | C25: 3392.497 | D25: 1474.334 | E25: 26.4 | F25: =D25/E25 -> 55.845984 | G25: 8.888 | H25: =F25*G25 -> 496.3591 | I25: =C25-D25 -> 1918.163 | J25: =I25/C25 -> 0.56541333 | K25: =J25-J24 -> 0.018581508 | L25: 3.6 | M25: =I25/L25 -> 532.82306 | N25: 348 | O25: =M25*N25*1000/1000000 -> 185.42243 | P25: =O25+H25 -> 681.78153 | Q25: ='Calcs by Scenario'!$P$10-P25 -> 416.69447 | R25: =150/L25 -> 41.666667 | S25: =R25*Rough1!$B$25/1000000/1000 -> 10.739217 | T25: =S25/C25*1000 -> 3.165579 | U25: =U24 -> 115 | V25: =S25*U25/1000 -> 1.23501 | W25: =V25/(Q25*Rough1!$B$26)*1000 -> 0.29638262 | X25: =V25/(I25*Rough1!$B$26)*1000 -> 0.064385038 | Y25: 3 | Z25: =Y25*F25 -> 167.53795 | AA25: 0.25 | AB25: =AA25*M25 -> 133.20577 | AC25: =AB25+Z25 -> 300.74372 | AD25: ='Calcs by Scenario'!$AC$10-AC25 -> 70.02901 | AE25: =AC25/C25 -> 0.088649663 | AF25: =AC25/Q25 -> 0.72173676 | AG25: 2832.2033 | AH25: 1918.163 | AI25: =AG25-AH25*($C$25/C25) -> 914.04026

Sheet Trip Bin Distance
A1: Trip Distance Bin (miles) | C1: Trips (B/year) | D1: Trips (B / month) | E1: Drivers | F1: Trips/Driver/month | G1: Trips / Week | H1: Households (MM) | I1: Trips/HH/week (derived) | J1: Trips / HH / week | K1: Trips / HH / year | L1: Round Trips / HH | M1: VMT | N1: Gas VMT / HH | O1: ELC VMT / HH | P1: Gas VMT | Q1: ELC VMT
A2: 0-1 | B2: 0.3 | C2: 146.472 | D2: =C2/12 -> 12.206 | E2: =D2*1000000000/F2 -> 1.2834695e+08 | F2: 95.1016 | G2: =C2/52 -> 2.8167692 | H2: =131.4 -> 131.4 | I2: 21.8876 | J2: =G2*1000/H2 -> 21.4366 | K2: =J2*52 -> 1114.7032 | L2: =K2/2 -> 557.3516 | M2: =K2*H2*B2/1000 -> 43.9416 | N2: =MAX((B2*2-$O$14)*L2,0)/1000 -> 0 | O2: =MIN($O$14,B2*2)*L2/1000 -> 0.33441096 | P2: =N2*H2 -> 0 | Q2: =O2*H2 -> 43.9416
A3: 1-3 | B3: 1 | C3: 123.019 | D3: =C3/12 -> 10.251583 | E3: =D3*1000000000/F3 -> 1.2838294e+08 | F3: 79.8516 | G3: =C3/52 -> 2.36575 | H3: =131.4 -> 131.4 | I3: 18.3778 | J3: =G3*1000/H3 -> 18.004186 | K3: =J3*52 -> 936.21766 | L3: =K3/2 -> 468.10883 | M3: =K3*H3*B3/1000 -> 123.019 | N3: =MAX((B3*2-$O$14)*L3,0)/1000 -> 0 | O3: =MIN($O$14,B3*2)*L3/1000 -> 0.93621766 | P3: =N3*H3 -> 0 | Q3: =O3*H3 -> 123.019
A4: 3-5 | B4: 3 | C4: 63.632 | D4: =C4/12 -> 5.3026667 | E4: =D4*1000000000/F4 -> 1.2779912e+08 | F4: 41.4922 | G4: =C4/52 -> 1.2236923 | H4: =131.4 -> 131.4 | I4: 9.5494 | J4: =G4*1000/H4 -> 9.3127268 | K4: =J4*52 -> 484.2618 | L4: =K4/2 -> 242.1309 | M4: =K4*H4*B4/1000 -> 190.896 | N4: =MAX((B4*2-$O$14)*L4,0)/1000 -> 0 | O4: =MIN($O$14,B4*2)*L4/1000 -> 1.4527854 | P4: =N4*H4 -> 0 | Q4: =O4*H4 -> 190.896
A5: 5-10 | B5: 5 | C5: 81.916 | D5: =C5/12 -> 6.8263333 | E5: =D5*1000000000/F5 -> 1.2646838e+08 | F5: 53.9766 | G5: =C5/52 -> 1.5753077 | H5: =131.4 -> 131.4 | I5: 12.4227 | J5: =G5*1000/H5 -> 11.988643 | K5: =J5*52 -> 623.40944 | L5: =K5/2 -> 311.70472 | M5: =K5*H5*B5/1000 -> 409.58 | N5: =MAX((B5*2-$O$14)*L5,0)/1000 -> 0 | O5: =MIN($O$14,B5*2)*L5/1000 -> 3.1170472 | P5: =N5*H5 -> 0 | Q5: =O5*H5 -> 409.58
A6: 10-25 | B6: 10 | C6: 77.731 | D6: =C6/12 -> 6.4775833 | E6: =D6*1000000000/F6 -> 1.2434461e+08 | F6: 52.0938 | G6: =C6/52 -> 1.4948269 | H6: =131.4 -> 131.4 | I6: 11.9894 | J6: =G6*1000/H6 -> 11.376156 | K6: =J6*52 -> 591.56012 | L6: =K6/2 -> 295.78006 | M6: =K6*H6*B6/1000 -> 777.31 | N6: =MAX((B6*2-$O$14)*L6,0)/1000 -> 0 | O6: =MIN($O$14,B6*2)*L6/1000 -> 5.9156012 | P6: =N6*H6 -> 0 | Q6: =O6*H6 -> 777.31
A7: 25-50 | B7: 25 | C7: 24.428 | D7: =C7/12 -> 2.0356667 | E7: =D7*1000000000/F7 -> 1.256344e+08 | F7: 16.2031 | G7: =C7/52 -> 0.46976923 | H7: =131.4 -> 131.4 | I7: 3.7291 | J7: =G7*1000/H7 -> 3.5751083 | K7: =J7*52 -> 185.90563 | L7: =K7/2 -> 92.952816 | M7: =K7*H7*B7/1000 -> 610.7 | N7: =MAX((B7*2-$O$14)*L7,0)/1000 -> 0 | O7: =MIN($O$14,B7*2)*L7/1000 -> 4.6476408 | P7: =N7*H7 -> 0 | Q7: =O7*H7 -> 610.7
A8: 50-100 | B8: 50 | C8: 8.245 | D8: =C8/12 -> 0.68708333 | E8: =D8*1000000000/F8 -> 1.2895466e+08 | F8: 5.3281 | G8: =C8/52 -> 0.15855769 | H8: =131.4 -> 131.4 | I8: 1.2263 | J8: =G8*1000/H8 -> 1.2066795 | K8: =J8*52 -> 62.747336 | L8: =K8/2 -> 31.373668 | M8: =K8*H8*B8/1000 -> 412.25 | N8: =MAX((B8*2-$O$14)*L8,0)/1000 -> 0 | O8: =MIN($O$14,B8*2)*L8/1000 -> 3.1373668 | P8: =N8*H8 -> 0 | Q8: =O8*H8 -> 412.25
A9: 100-250 | B9: 100 | C9: 3.748 | D9: =C9/12 -> 0.31233333 | E9: =D9*1000000000/F9 -> 1.3150877e+08 | F9: 2.375 | G9: =C9/52 -> 0.072076923 | H9: =131.4 -> 131.4 | I9: 0.5466 | J9: =G9*1000/H9 -> 0.54853062 | K9: =J9*52 -> 28.523592 | L9: =K9/2 -> 14.261796 | M9: =K9*H9*B9/1000 -> 374.8 | N9: =MAX((B9*2-$O$14)*L9,0)/1000 -> 0.7130898 | O9: =MIN($O$14,B9*2)*L9/1000 -> 2.1392694 | P9: =N9*H9 -> 93.7 | Q9: =O9*H9 -> 281.1
A10: 250+500 | B10: 250 | C10: 0.774 | D10: =C10/12 -> 0.0645 | E10: =D10*1000000000/F10 -> 1.3315442e+08 | F10: 0.4844 | G10: =C10/52 -> 0.014884615 | H10: =131.4 -> 131.4 | I10: 0.1115 | J10: =G10*1000/H10 -> 0.11327713 | K10: =J10*52 -> 5.890411 | L10: =K10/2 -> 2.9452055 | M10: =K10*H10*B10/1000 -> 193.5 | N10: =MAX((B10*2-$O$14)*L10,0)/1000 -> 1.0308219 | O10: =MIN($O$14,B10*2)*L10/1000 -> 0.44178082 | P10: =N10*H10 -> 135.45 | Q10: =O10*H10 -> 58.05
A11: 500+ | B11: 500 | C11: 0.513 | D11: =C11/12 -> 0.04275 | E11: =D11*1000000000/F11 -> 1.2434555e+08 | F11: 0.3438 | G11: =C11/52 -> 0.0098653846 | H11: =131.4 -> 131.4 | I11: 0.0791 | J11: =G11*1000/H11 -> 0.075079031 | K11: =J11*52 -> 3.9041096 | L11: =K11/2 -> 1.9520548 | M11: =K11*H11*B11/1000 -> 256.5 | N11: =MAX((B11*2-$O$14)*L11,0)/1000 -> 1.6592466 | O11: =MIN($O$14,B11*2)*L11/1000 -> 0.29280822 | P11: =N11*H11 -> 218.025 | Q11: =O11*H11 -> 38.475
M12: =SUM(M2:M11) -> 3392.4966 | N12: =SUM(N2:N11) -> 3.4031583 | O12: =SUM(O2:O11) -> 22.414928 | P12: =SUM(P2:P11) -> 447.175 | Q12: =SUM(Q2:Q11) -> 2945.3216
M13: VMT / HH | N13: =N12+O12 -> 25.818087 | Q13: =Q12+P12 -> 3392.4966 | R13: VMT (Bin Calc)
N14: Range | O14: 150
F15: VMT (Bin Calc) | G15: =SUMPRODUCT(G2:G11,B2:B11)*52 -> 3392.4966 | I15: =SUMPRODUCT(J2:J11,B2:B11)*52*131.4/1000 -> 3392.4966
F16: VMT / HH (Calc) | G16: =G15/H11 -> 25.818087 | J16: =SUM(J2:J8) -> 76.9001
F18: True VMT | G18: 3262.8
F19: VMT / HH (True) | G19: =G18/H11 -> 24.83105
G22: =(G15-G18)/G18 -> 0.039750092

Sheet Table 4
A1: Parameters | B1: Value (Worst / Average / Best) | C1: Source
A2: Average Fuel Economy | B2: 18 / 26.4 / 36 mpg
A3: CO2 per Gallon of Gasoline | B3: 8.888 kg / CO2
A4: CO2 per Gallon of Diesel | B4: 10.18 kg / CO2
A5: EV Energy Use per Mile | B5: 2.9 / 3.6 / 4.2 mi / kWh
A6: EV Average Fuel Economy | B6: 97.75 / 121.3 / 141.6 mpge
A7: Average US Grid CO2 Intensity | B7: 125 / 348 / 714 g CO2 / kWh
A8: Average Retail Electricity Price | B8: $0.15 /$ 0.25 / $0.40 / kWh
A9: Average Gasoline Price | B9: $2 / $3 / $5
A10: Average VMT per Year | B10: 11408
A11: Average VMT per Driver per Year | B11: 13476
A12: Total VMT (B, 2023) | B12: 3262.8
A13: Vehicle Count | B13: 286 M

Sheet Table  5
A1: Scenario | B1: Vehicle Type | C1: Gas VMT (B) | D1: MPG | E1: Gallons (B) | F1: Gas Emissions (M tons CO2) | G1: Electric VMT (B) | H1: mi / kWh | I1: Electricity (TWh) | J1: Electricity Emissions (Mt CO2) | K1: Total Emissions (M t CO2) | L1: CO2 Saved (Mt CO2) | M1: Average Battery Size (kWh) | N1: Installed Battery (TWh) | O1: Cost / kWh | P1: $T Installed Battery | Q1: $ CAPEX / kg CO2 | R1: $ CAPEX / EV Mile | S1: $ / gallon | T1: $ B OC Gas | U1: $ / kWh | V1: $B OC ELC | W1: $B OC Total | X1: $B ELC Savings | Y1: $ OC / VMT | Z1: $OC / kg CO2
A2: Worst | B2: ICE | C2: 3262.8 | D2: 36 | E2: 90.633333 | F2: 805.54907 | G2: 0 | H2: 2.9 | I2: 0 | J2: 0 | K2: 805.54907 | L2: 0 | M2: 0 | N2: 0 | O2: 150 | P2: 0 | Q2: N/A | R2: N/A | S2: 2 | T2: 181.26667 | U2: 0.4 | V2: 0 | W2: 181.26667 | X2: 0 | Y2: 0.055555556 | Z2: N/A
A3: Worst | B3: LDV (25-mile EV range) | C3: 1326.0507 | D3: 36 | E3: 36.834743 | F3: 327.38719 | G3: 1936.7493 | H3: 2.9 | I3: 667.84457 | J3: 476.84102 | K3: 804.22822 | L3: 1.3208482 | M3: 8.6206897 | N3: 2.221907 | O3: 150 | P3: 0.33328606 | Q3: 25.232731 | R3: 0.017208529 | S3: 2 | T3: 73.669486 | U3: 0.4 | V3: 267.13783 | W3: 340.80731 | X3: -159.54065 | Y3: 0.10445241 | Z3: 258.02157
A4: Worst | B4: LDV (50-mile EV range) | C4: 871.73127 | D4: 36 | E4: 24.214758 | F4: 215.22076 | G4: 2391.0687 | H4: 2.9 | I4: 824.50646 | J4: 588.69761 | K4: 803.91838 | L4: 1.6306906 | M4: 17.241379 | N4: 4.4438141 | O4: 150 | P4: 0.66657211 | Q4: 40.876677 | R4: 0.027877581 | S4: 2 | T4: 48.429515 | U4: 0.4 | V4: 329.80258 | W4: 378.2321 | X4: -196.96543 | Y4: 0.11592255 | Z4: 231.94597
A5: Worst | B5: LDV (75-mile EV range) | C5: 711.79192 | D5: 36 | E5: 19.771998 | F5: 175.73352 | G5: 2551.0081 | H5: 2.9 | I5: 879.65796 | J5: 628.07578 | K5: 803.8093 | L5: 1.739768 | M5: 25.862069 | N5: 6.6657211 | O5: 150 | P5: 0.99985817 | Q5: 57.470777 | R5: 0.03919463 | S5: 2 | T5: 39.543996 | U5: 0.4 | V5: 351.86318 | W5: 391.40718 | X5: -210.14051 | Y5: 0.11996052 | Z5: 224.97666
A6: Worst | B6: LDV (100-mile EV range) | C6: 551.85257 | D6: 36 | E6: 15.329238 | F6: 136.24627 | G6: 2710.9474 | H6: 2.9 | I6: 934.80946 | J6: 667.45395 | K6: 803.70022 | L6: 1.8488454 | M6: 34.482759 | N6: 8.8876282 | O6: 150 | P6: 1.3331442 | Q6: 72.106854 | R6: 0.049176322 | S6: 2 | T6: 30.658476 | U6: 0.4 | V6: 373.92378 | W6: 404.58226 | X6: -223.31559 | Y6: 0.12399849 | Z6: 218.82969
A7: Worst | B7: LDV (125-mile EV range) | C7: 491.22464 | D7: 36 | E7: 13.645129 | F7: 121.27791 | G7: 2771.5754 | H7: 2.9 | I7: 955.71564 | J7: 682.38097 | K7: 803.65887 | L7: 1.8901932 | M7: 43.103448 | N7: 11.109535 | O7: 150 | P7: 1.6664303 | Q7: 88.161904 | R7: 0.060125743 | S7: 2 | T7: 27.290258 | U7: 0.4 | V7: 382.28626 | W7: 409.57651 | X7: -228.30985 | Y7: 0.12552915 | Z7: 216.68501
A8: Worst | B8: LDV (150-mile EV range) | C8: 430.59671 | D8: 36 | E8: 11.96102 | F8: 106.30954 | G8: 2832.2033 | H8: 2.9 | I8: 976.62183 | J8: 697.30798 | K8: 803.61753 | L8: 1.9315409 | M8: 51.724138 | N8: 13.331442 | O8: 150 | P8: 1.9997163 | Q8: 103.52959 | R8: 0.070606384 | S8: 2 | T8: 23.922039 | U8: 0.4 | V8: 390.64873 | W8: 414.57077 | X8: -233.3041 | Y8: 0.12705982 | Z8: 214.63214
A9: Worst | B9: EV | C9: 0 | D9: 36 | E9: 0 | F9: 0 | G9: 3262.8 | H9: 2.9 | I9: 1125.1034 | J9: 803.32386 | K9: 803.32386 | L9: 2.2252046 | M9: 103.44828 | N9: 26.662885 | O9: 150 | P9: 3.9994327 | Q9: 179.73326 | R9: 0.1225767 | S9: 2 | T9: 0 | U9: 0.4 | V9: 450.04138 | W9: 450.04138 | X9: -268.77471 | Y9: 0.13793103 | Z9: 202.24719
A10: Average | B10: ICE | C10: 3262.8 | D10: 26.4 | E10: 123.59091 | F10: 1098.476 | G10: 0 | H10: 3.6 | I10: 0 | J10: 0 | K10: 1098.476 | L10: 0 | M10: 0 | N10: 0 | O10: 115 | P10: 0 | Q10: N/A | R10: N/A | S10: 3 | T10: 370.77273 | U10: 0.25 | V10: 0 | W10: 370.77273 | X10: 0 | Y10: 0.11363636 | Z10: N/A
A11: Average | B11: LDV (25-mile EV range) | C11: 1326.0507 | D11: 26.4 | E11: 50.229195 | F11: 446.43708 | G11: 1936.7493 | H11: 3.6 | I11: 537.98591 | J11: 187.21909 | K11: 633.65618 | L11: 464.81982 | M11: 6.9444444 | N11: 1.7898696 | O11: 115 | P11: 0.205835 | Q11: 0.04428275 | R11: 0.01062786 | S11: 3 | T11: 150.68758 | U11: 0.25 | V11: 134.49648 | W11: 285.18406 | X11: 85.588667 | Y11: 0.087404702 | Z11: 0.61353679
A12: Average | B12: LDV (50-mile EV range) | C12: 871.73127 | D12: 26.4 | E12: 33.020124 | F12: 293.48286 | G12: 2391.0687 | H12: 3.6 | I12: 664.18576 | J12: 231.13664 | K12: 524.6195 | L12: 573.8565 | M12: 13.888889 | N12: 3.5797391 | O12: 115 | P12: 0.41167 | Q12: 0.071737447 | R12: 0.017216987 | S12: 3 | T12: 99.060372 | U12: 0.25 | V12: 166.04644 | W12: 265.10681 | X12: 105.66592 | Y12: 0.081251321 | Z12: 0.46197405
A13: Average | B13: LDV (75-mile EV range) | C13: 711.79192 | D13: 26.4 | E13: 26.961815 | F13: 239.63661 | G13: 2551.0081 | H13: 3.6 | I13: 708.61336 | J13: 246.59745 | K13: 486.23406 | L13: 612.24194 | M13: 20.833333 | N13: 5.3696087 | O13: 115 | P13: 0.617505 | Q13: 0.10085964 | R13: 0.024206313 | S13: 3 | T13: 80.885445 | U13: 0.25 | V13: 177.15334 | W13: 258.03878 | X13: 112.73394 | Y13: 0.079085076 | Z13: 0.42146538
